<?xml version="1.0" ?>
<robot name="ros_robot" xmlns:xacro="http://ros.org/wiki/xacro">
  <xacro:include filename="$(find robot_description)/urdf/common_properties.xacro"/>
  <xacro:include filename="$(find robot_description)/urdf/robot_chassis.gazebo2.xacro"/>
  <link name="base_footprint"/>

  <joint name="base_joint" type="fixed">
    <parent link="base_footprint"/>
    <child link="base_link" />
    <origin xyz="0 0 0.010" rpy="0 0 0"/>
  </joint>

  <link name="base_link">
    <visual>
      <origin xyz="-0.064 0.0 0.0473" rpy="0 0 1.57"/>
      <geometry>
        <mesh filename="package://robot_description/meshes/Chassis.stl" scale="0.001 0.001 0.001"/>
      </geometry>
      <material name="light_black"/>
    </visual>

    <collision>
      <origin xyz="-0.064 0 0.0473" rpy="0 0 1.57"/>
      <geometry>
        <box size="0.1 0.19 0.08"/>
      </geometry>
    </collision>

    <inertial>
      <origin xyz="0 0 0" rpy="0 0 0"/>
      <mass value="0.532"/>
      <inertia ixx="0.001" ixy="0.000" ixz="0.00"
               iyy="0.001" iyz="0.000"
               izz="0.001" />
    </inertial>
  </link>

  <joint name="wheel_left_joint" type="continuous">
    <parent link="base_link"/>
    <child link="wheel_left_link"/>
    <origin xyz="-0.082 -0.053 0.034" rpy="0 -1.57 1.57"/>
    <axis xyz="0 0 1"/>
  </joint>

  <link name="wheel_left_link">
    <visual>
      <origin xyz="0.0 0.0 0.0 " rpy="0 0 0 "/>
      <geometry>
        <mesh filename="package://robot_description/meshes/left_tire.stl" scale="0.001 0.001 0.001"/>
      </geometry>
      <material name="orange"/>
    </visual>

    <collision>
      <origin xyz="0.0 0.0 0.0" rpy="0 0 0"/>
      <geometry>
        <cylinder length="0.025" radius="0.0325"/>
      </geometry>
    </collision>

    <inertial>
      <origin xyz="0 0 0" />
      <mass value="0.049" />
      <inertia ixx="3.07e-5" ixy="0.00" ixz="0.00"
               iyy="3.07e-5" iyz="0.00"
               izz="3.89e-5" />
      </inertial>
  </link>

  <joint name="wheel_right_joint" type="continuous">
    <parent link="base_link"/>
    <child link="wheel_right_link"/>
    <origin xyz="-0.082 0.053 0.034" rpy="0 -1.57 -1.57"/>
    <axis xyz="0 0 -1"/>
  </joint>

  <link name="wheel_right_link">
    <visual>
      <origin xyz="0.0 0.0 0.0" rpy="0 0 0"/>
      <geometry>
        <mesh filename="package://robot_description/meshes/right_tire.stl" scale="0.001 0.001 0.001"/>
      </geometry>
      <material name="orange"/>
    </visual>

    <collision>
      <origin xyz="0.0 0.0 0.0" rpy="0 0 0"/>
      <geometry>
        <cylinder length="0.025" radius="0.0325"/>
      </geometry>
    </collision>

     <inertial>
      <origin xyz="0 0 0" />
      <mass value="0.049" />
      <inertia ixx="3.07e-5" ixy="0.00" ixz="0.00"
               iyy="3.07e-5" iyz="0.00"
               izz="3.89e-5" />
      </inertial>
  </link>

  <joint name="caster_joint" type="fixed">
    <parent link="base_link"/>
    <child link="caster_link"/>
    <origin xyz="0.01 0 0.034" rpy="-1.57 0 1.57"/>
  </joint>

  <link name="caster_link">
	<visual>
      <origin xyz="0.0 0.0 0.0" rpy="0 0 0"/>
      <geometry>
        <mesh filename="package://robot_description/meshes/Caster_Wheel.stl" scale="0.001 0.001 0.001"/>
      </geometry>
      <material name="dark"/>
    </visual>    

	<collision>
      <origin xyz="0 0 -0.01" rpy="0 0 0"/>
      <geometry>
        <sphere radius="0.02"/>
      </geometry>
    </collision>

    <inertial>
      <origin xyz="0 0 0" />
      <mass value="0.039" />
      <inertia ixx="1.03e-5" ixy="-2.13e-8" ixz="1.22e-8"
               iyy="7.52e-6" iyz="-3.19e-6"
               izz="8.86e-6" />
    </inertial>
  </link>

  <joint name="scan_joint" type="fixed">
    <parent link="base_link"/>
    <child link="laser"/>
    <origin xyz="-0.120 0 0.08" rpy="0 0 0"/>
  </joint>

  <link name="laser">
    <visual>
      <origin xyz="0.0 0.0 0.0" rpy="0 0 0"/>
      <geometry>
        <mesh filename="package://robot_description/meshes/lds.stl" scale="0.001 0.001 0.001"/>
      </geometry>
      <material name="dark"/>
    </visual>

    <collision>
      <origin xyz="0.0 0 0.0" rpy="0 0 0"/>
      <geometry>
        <cylinder length="0.021" radius="0.055"/>
      </geometry>
    </collision>

    <inertial>
      <mass value="0.114" />
      <origin xyz="0 0 0" />
      <inertia ixx="0.001" ixy="0.0" ixz="0.0"
               iyy="0.001" iyz="0.0"
               izz="0.001" />
    </inertial>
  </link>

  <joint name="imu_joint" type="fixed">
    <parent link="base_link"/>
    <child link="imu_link"/>
    <origin xyz="0.0 0 0.068" rpy="0 0 0"/>
  </joint>

  <link name="imu_link"/>


</robot>
